2022-03-25 00:09:33,941 | WARNING | LUNO request failed, retrying..., retry count: 1
2022-03-25 00:09:33,941 | WARNING | LUNO request failed, retrying..., retry count: 1
2022-03-25 00:09:49,193 | WARNING | LUNO request failed, retrying..., retry count: 2
2022-03-25 00:09:49,193 | WARNING | LUNO request failed, retrying..., retry count: 2
2022-03-25 00:10:09,227 | WARNING | LUNO request failed, retrying..., retry count: 3
2022-03-25 00:10:09,227 | WARNING | LUNO request failed, retrying..., retry count: 3
2022-03-25 00:10:29,304 | WARNING | Error: Traceback (most recent call last):
  File "/home/pi/cryptobot/venv/lib/python3.9/site-packages/urllib3/connection.py", line 174, in _new_conn
    conn = connection.create_connection(
  File "/home/pi/cryptobot/venv/lib/python3.9/site-packages/urllib3/util/connection.py", line 72, in create_connection
    for res in socket.getaddrinfo(host, port, family, socket.SOCK_STREAM):
  File "/usr/lib/python3.9/socket.py", line 953, in getaddrinfo
    for res in _socket.getaddrinfo(host, port, family, type, proto, flags):
socket.gaierror: [Errno -3] Temporary failure in name resolution

During handling of the above exception, another exception occurred:

Traceback (most recent call last):
  File "/home/pi/cryptobot/venv/lib/python3.9/site-packages/urllib3/connectionpool.py", line 703, in urlopen
    httplib_response = self._make_request(
  File "/home/pi/cryptobot/venv/lib/python3.9/site-packages/urllib3/connectionpool.py", line 386, in _make_request
    self._validate_conn(conn)
  File "/home/pi/cryptobot/venv/lib/python3.9/site-packages/urllib3/connectionpool.py", line 1040, in _validate_conn
    conn.connect()
  File "/home/pi/cryptobot/venv/lib/python3.9/site-packages/urllib3/connection.py", line 358, in connect
    conn = self._new_conn()
  File "/home/pi/cryptobot/venv/lib/python3.9/site-packages/urllib3/connection.py", line 186, in _new_conn
    raise NewConnectionError(
urllib3.exceptions.NewConnectionError: <urllib3.connection.HTTPSConnection object at 0x7308fa78>: Failed to establish a new connection: [Errno -3] Temporary failure in name resolution

During handling of the above exception, another exception occurred:

Traceback (most recent call last):
  File "/home/pi/cryptobot/venv/lib/python3.9/site-packages/requests/adapters.py", line 440, in send
    resp = conn.urlopen(
  File "/home/pi/cryptobot/venv/lib/python3.9/site-packages/urllib3/connectionpool.py", line 785, in urlopen
    retries = retries.increment(
  File "/home/pi/cryptobot/venv/lib/python3.9/site-packages/urllib3/util/retry.py", line 592, in increment
    raise MaxRetryError(_pool, url, error or ResponseError(cause))
urllib3.exceptions.MaxRetryError: HTTPSConnectionPool(host='api.luno.com', port=443): Max retries exceeded with url: /api/1/balance?assets=ZAR (Caused by NewConnectionError('<urllib3.connection.HTTPSConnection object at 0x7308fa78>: Failed to establish a new connection: [Errno -3] Temporary failure in name resolution'))

During handling of the above exception, another exception occurred:

Traceback (most recent call last):
  File "/home/pi/cryptobot/modules/luno.py", line 23, in do_get_request
    response = requests.get(url, auth=HTTPBasicAuth(KEY_ID, SECRET), params=params)
  File "/home/pi/cryptobot/venv/lib/python3.9/site-packages/requests/api.py", line 75, in get
    return request('get', url, params=params, **kwargs)
  File "/home/pi/cryptobot/venv/lib/python3.9/site-packages/requests/api.py", line 61, in request
    return session.request(method=method, url=url, **kwargs)
  File "/home/pi/cryptobot/venv/lib/python3.9/site-packages/requests/sessions.py", line 529, in request
    resp = self.send(prep, **send_kwargs)
  File "/home/pi/cryptobot/venv/lib/python3.9/site-packages/requests/sessions.py", line 645, in send
    r = adapter.send(request, **kwargs)
  File "/home/pi/cryptobot/venv/lib/python3.9/site-packages/requests/adapters.py", line 519, in send
    raise ConnectionError(e, request=request)
requests.exceptions.ConnectionError: HTTPSConnectionPool(host='api.luno.com', port=443): Max retries exceeded with url: /api/1/balance?assets=ZAR (Caused by NewConnectionError('<urllib3.connection.HTTPSConnection object at 0x7308fa78>: Failed to establish a new connection: [Errno -3] Temporary failure in name resolution'))

During handling of the above exception, another exception occurred:

Traceback (most recent call last):
  File "/home/pi/cryptobot/main.py", line 155, in <module>
    main()
  File "/home/pi/cryptobot/main.py", line 149, in main
    schedule.run_pending()
  File "/home/pi/cryptobot/venv/lib/python3.9/site-packages/schedule/__init__.py", line 780, in run_pending
    default_scheduler.run_pending()
  File "/home/pi/cryptobot/venv/lib/python3.9/site-packages/schedule/__init__.py", line 100, in run_pending
    self._run_job(job)
  File "/home/pi/cryptobot/venv/lib/python3.9/site-packages/schedule/__init__.py", line 172, in _run_job
    ret = job.run()
  File "/home/pi/cryptobot/venv/lib/python3.9/site-packages/schedule/__init__.py", line 661, in run
    ret = self.job_func()
  File "/home/pi/cryptobot/main.py", line 107, in handle_buy_orders
    handle_update(bot)
  File "/home/pi/cryptobot/main.py", line 103, in handle_update
    bot.run_update()
  File "/home/pi/cryptobot/main.py", line 68, in run_update
    self.update_funds()
  File "/home/pi/cryptobot/classes/funds_manager.py", line 9, in update_funds
    self.funds = self.get_funds()
  File "/home/pi/cryptobot/classes/funds_manager.py", line 12, in get_funds
    funds = float(luno.get_spendable_balance())
  File "/home/pi/cryptobot/modules/luno.py", line 108, in get_spendable_balance
    account_balance = get_account_balance(currency)['balance'][0]
  File "/home/pi/cryptobot/modules/luno.py", line 121, in get_account_balance
    return do_get_request(f'{BASE_URL}1/balance', params)
  File "/home/pi/cryptobot/modules/luno.py", line 28, in do_get_request
    raise Exception('Max retry count reached')
Exception: Max retry count reached

2022-03-25 00:10:29,304 | WARNING | Error: Traceback (most recent call last):
  File "/home/pi/cryptobot/venv/lib/python3.9/site-packages/urllib3/connection.py", line 174, in _new_conn
    conn = connection.create_connection(
  File "/home/pi/cryptobot/venv/lib/python3.9/site-packages/urllib3/util/connection.py", line 72, in create_connection
    for res in socket.getaddrinfo(host, port, family, socket.SOCK_STREAM):
  File "/usr/lib/python3.9/socket.py", line 953, in getaddrinfo
    for res in _socket.getaddrinfo(host, port, family, type, proto, flags):
socket.gaierror: [Errno -3] Temporary failure in name resolution

During handling of the above exception, another exception occurred:

Traceback (most recent call last):
  File "/home/pi/cryptobot/venv/lib/python3.9/site-packages/urllib3/connectionpool.py", line 703, in urlopen
    httplib_response = self._make_request(
  File "/home/pi/cryptobot/venv/lib/python3.9/site-packages/urllib3/connectionpool.py", line 386, in _make_request
    self._validate_conn(conn)
  File "/home/pi/cryptobot/venv/lib/python3.9/site-packages/urllib3/connectionpool.py", line 1040, in _validate_conn
    conn.connect()
  File "/home/pi/cryptobot/venv/lib/python3.9/site-packages/urllib3/connection.py", line 358, in connect
    conn = self._new_conn()
  File "/home/pi/cryptobot/venv/lib/python3.9/site-packages/urllib3/connection.py", line 186, in _new_conn
    raise NewConnectionError(
urllib3.exceptions.NewConnectionError: <urllib3.connection.HTTPSConnection object at 0x7308fa78>: Failed to establish a new connection: [Errno -3] Temporary failure in name resolution

During handling of the above exception, another exception occurred:

Traceback (most recent call last):
  File "/home/pi/cryptobot/venv/lib/python3.9/site-packages/requests/adapters.py", line 440, in send
    resp = conn.urlopen(
  File "/home/pi/cryptobot/venv/lib/python3.9/site-packages/urllib3/connectionpool.py", line 785, in urlopen
    retries = retries.increment(
  File "/home/pi/cryptobot/venv/lib/python3.9/site-packages/urllib3/util/retry.py", line 592, in increment
    raise MaxRetryError(_pool, url, error or ResponseError(cause))
urllib3.exceptions.MaxRetryError: HTTPSConnectionPool(host='api.luno.com', port=443): Max retries exceeded with url: /api/1/balance?assets=ZAR (Caused by NewConnectionError('<urllib3.connection.HTTPSConnection object at 0x7308fa78>: Failed to establish a new connection: [Errno -3] Temporary failure in name resolution'))

During handling of the above exception, another exception occurred:

Traceback (most recent call last):
  File "/home/pi/cryptobot/modules/luno.py", line 23, in do_get_request
    response = requests.get(url, auth=HTTPBasicAuth(KEY_ID, SECRET), params=params)
  File "/home/pi/cryptobot/venv/lib/python3.9/site-packages/requests/api.py", line 75, in get
    return request('get', url, params=params, **kwargs)
  File "/home/pi/cryptobot/venv/lib/python3.9/site-packages/requests/api.py", line 61, in request
    return session.request(method=method, url=url, **kwargs)
  File "/home/pi/cryptobot/venv/lib/python3.9/site-packages/requests/sessions.py", line 529, in request
    resp = self.send(prep, **send_kwargs)
  File "/home/pi/cryptobot/venv/lib/python3.9/site-packages/requests/sessions.py", line 645, in send
    r = adapter.send(request, **kwargs)
  File "/home/pi/cryptobot/venv/lib/python3.9/site-packages/requests/adapters.py", line 519, in send
    raise ConnectionError(e, request=request)
requests.exceptions.ConnectionError: HTTPSConnectionPool(host='api.luno.com', port=443): Max retries exceeded with url: /api/1/balance?assets=ZAR (Caused by NewConnectionError('<urllib3.connection.HTTPSConnection object at 0x7308fa78>: Failed to establish a new connection: [Errno -3] Temporary failure in name resolution'))

During handling of the above exception, another exception occurred:

Traceback (most recent call last):
  File "/home/pi/cryptobot/main.py", line 155, in <module>
    main()
  File "/home/pi/cryptobot/main.py", line 149, in main
    schedule.run_pending()
  File "/home/pi/cryptobot/venv/lib/python3.9/site-packages/schedule/__init__.py", line 780, in run_pending
    default_scheduler.run_pending()
  File "/home/pi/cryptobot/venv/lib/python3.9/site-packages/schedule/__init__.py", line 100, in run_pending
    self._run_job(job)
  File "/home/pi/cryptobot/venv/lib/python3.9/site-packages/schedule/__init__.py", line 172, in _run_job
    ret = job.run()
  File "/home/pi/cryptobot/venv/lib/python3.9/site-packages/schedule/__init__.py", line 661, in run
    ret = self.job_func()
  File "/home/pi/cryptobot/main.py", line 107, in handle_buy_orders
    handle_update(bot)
  File "/home/pi/cryptobot/main.py", line 103, in handle_update
    bot.run_update()
  File "/home/pi/cryptobot/main.py", line 68, in run_update
    self.update_funds()
  File "/home/pi/cryptobot/classes/funds_manager.py", line 9, in update_funds
    self.funds = self.get_funds()
  File "/home/pi/cryptobot/classes/funds_manager.py", line 12, in get_funds
    funds = float(luno.get_spendable_balance())
  File "/home/pi/cryptobot/modules/luno.py", line 108, in get_spendable_balance
    account_balance = get_account_balance(currency)['balance'][0]
  File "/home/pi/cryptobot/modules/luno.py", line 121, in get_account_balance
    return do_get_request(f'{BASE_URL}1/balance', params)
  File "/home/pi/cryptobot/modules/luno.py", line 28, in do_get_request
    raise Exception('Max retry count reached')
Exception: Max retry count reached

2022-03-25 00:10:29,304 | WARNING | Error: Traceback (most recent call last):
  File "/home/pi/cryptobot/venv/lib/python3.9/site-packages/urllib3/connection.py", line 174, in _new_conn
    conn = connection.create_connection(
  File "/home/pi/cryptobot/venv/lib/python3.9/site-packages/urllib3/util/connection.py", line 72, in create_connection
    for res in socket.getaddrinfo(host, port, family, socket.SOCK_STREAM):
  File "/usr/lib/python3.9/socket.py", line 953, in getaddrinfo
    for res in _socket.getaddrinfo(host, port, family, type, proto, flags):
socket.gaierror: [Errno -3] Temporary failure in name resolution

During handling of the above exception, another exception occurred:

Traceback (most recent call last):
  File "/home/pi/cryptobot/venv/lib/python3.9/site-packages/urllib3/connectionpool.py", line 703, in urlopen
    httplib_response = self._make_request(
  File "/home/pi/cryptobot/venv/lib/python3.9/site-packages/urllib3/connectionpool.py", line 386, in _make_request
    self._validate_conn(conn)
  File "/home/pi/cryptobot/venv/lib/python3.9/site-packages/urllib3/connectionpool.py", line 1040, in _validate_conn
    conn.connect()
  File "/home/pi/cryptobot/venv/lib/python3.9/site-packages/urllib3/connection.py", line 358, in connect
    conn = self._new_conn()
  File "/home/pi/cryptobot/venv/lib/python3.9/site-packages/urllib3/connection.py", line 186, in _new_conn
    raise NewConnectionError(
urllib3.exceptions.NewConnectionError: <urllib3.connection.HTTPSConnection object at 0x7308fa78>: Failed to establish a new connection: [Errno -3] Temporary failure in name resolution

During handling of the above exception, another exception occurred:

Traceback (most recent call last):
  File "/home/pi/cryptobot/venv/lib/python3.9/site-packages/requests/adapters.py", line 440, in send
    resp = conn.urlopen(
  File "/home/pi/cryptobot/venv/lib/python3.9/site-packages/urllib3/connectionpool.py", line 785, in urlopen
    retries = retries.increment(
  File "/home/pi/cryptobot/venv/lib/python3.9/site-packages/urllib3/util/retry.py", line 592, in increment
    raise MaxRetryError(_pool, url, error or ResponseError(cause))
urllib3.exceptions.MaxRetryError: HTTPSConnectionPool(host='api.luno.com', port=443): Max retries exceeded with url: /api/1/balance?assets=ZAR (Caused by NewConnectionError('<urllib3.connection.HTTPSConnection object at 0x7308fa78>: Failed to establish a new connection: [Errno -3] Temporary failure in name resolution'))

During handling of the above exception, another exception occurred:

Traceback (most recent call last):
  File "/home/pi/cryptobot/modules/luno.py", line 23, in do_get_request
    response = requests.get(url, auth=HTTPBasicAuth(KEY_ID, SECRET), params=params)
  File "/home/pi/cryptobot/venv/lib/python3.9/site-packages/requests/api.py", line 75, in get
    return request('get', url, params=params, **kwargs)
  File "/home/pi/cryptobot/venv/lib/python3.9/site-packages/requests/api.py", line 61, in request
    return session.request(method=method, url=url, **kwargs)
  File "/home/pi/cryptobot/venv/lib/python3.9/site-packages/requests/sessions.py", line 529, in request
    resp = self.send(prep, **send_kwargs)
  File "/home/pi/cryptobot/venv/lib/python3.9/site-packages/requests/sessions.py", line 645, in send
    r = adapter.send(request, **kwargs)
  File "/home/pi/cryptobot/venv/lib/python3.9/site-packages/requests/adapters.py", line 519, in send
    raise ConnectionError(e, request=request)
requests.exceptions.ConnectionError: HTTPSConnectionPool(host='api.luno.com', port=443): Max retries exceeded with url: /api/1/balance?assets=ZAR (Caused by NewConnectionError('<urllib3.connection.HTTPSConnection object at 0x7308fa78>: Failed to establish a new connection: [Errno -3] Temporary failure in name resolution'))

During handling of the above exception, another exception occurred:

Traceback (most recent call last):
  File "/home/pi/cryptobot/main.py", line 155, in <module>
    main()
  File "/home/pi/cryptobot/main.py", line 149, in main
    schedule.run_pending()
  File "/home/pi/cryptobot/venv/lib/python3.9/site-packages/schedule/__init__.py", line 780, in run_pending
    default_scheduler.run_pending()
  File "/home/pi/cryptobot/venv/lib/python3.9/site-packages/schedule/__init__.py", line 100, in run_pending
    self._run_job(job)
  File "/home/pi/cryptobot/venv/lib/python3.9/site-packages/schedule/__init__.py", line 172, in _run_job
    ret = job.run()
  File "/home/pi/cryptobot/venv/lib/python3.9/site-packages/schedule/__init__.py", line 661, in run
    ret = self.job_func()
  File "/home/pi/cryptobot/main.py", line 107, in handle_buy_orders
    handle_update(bot)
  File "/home/pi/cryptobot/main.py", line 103, in handle_update
    bot.run_update()
  File "/home/pi/cryptobot/main.py", line 68, in run_update
    self.update_funds()
  File "/home/pi/cryptobot/classes/funds_manager.py", line 9, in update_funds
    self.funds = self.get_funds()
  File "/home/pi/cryptobot/classes/funds_manager.py", line 12, in get_funds
    funds = float(luno.get_spendable_balance())
  File "/home/pi/cryptobot/modules/luno.py", line 108, in get_spendable_balance
    account_balance = get_account_balance(currency)['balance'][0]
  File "/home/pi/cryptobot/modules/luno.py", line 121, in get_account_balance
    return do_get_request(f'{BASE_URL}1/balance', params)
  File "/home/pi/cryptobot/modules/luno.py", line 28, in do_get_request
    raise Exception('Max retry count reached')
Exception: Max retry count reached

