2022-04-16 09:31:48,545 | INFO | Running AlgoBot...
2022-04-16 09:31:48,551 | WARNING | Error: Traceback (most recent call last):
  File "main.py", line 159, in <module>
    main()
  File "main.py", line 140, in main
    bot = initialize_bot()
  File "main.py", line 80, in initialize_bot
    bot.get_prices()
  File "/Users/darrenpaul/Documents/development/personal/cryptobot/classes/price_manager.py", line 38, in get_prices
    prices = file_reader.read_yaml(file_path)
  File "/Users/darrenpaul/Documents/development/personal/cryptobot/modules/file_reader.py", line 12, in read_yaml
    return yaml.load(file, Loader=yaml.FullLoader)
  File "/Users/darrenpaul/Documents/development/personal/cryptobot/venv/lib/python3.8/site-packages/yaml/__init__.py", line 79, in load
    loader = Loader(stream)
  File "/Users/darrenpaul/Documents/development/personal/cryptobot/venv/lib/python3.8/site-packages/yaml/loader.py", line 24, in __init__
    Reader.__init__(self, stream)
  File "/Users/darrenpaul/Documents/development/personal/cryptobot/venv/lib/python3.8/site-packages/yaml/reader.py", line 85, in __init__
    self.determine_encoding()
  File "/Users/darrenpaul/Documents/development/personal/cryptobot/venv/lib/python3.8/site-packages/yaml/reader.py", line 135, in determine_encoding
    self.update(1)
  File "/Users/darrenpaul/Documents/development/personal/cryptobot/venv/lib/python3.8/site-packages/yaml/reader.py", line 169, in update
    self.check_printable(data)
  File "/Users/darrenpaul/Documents/development/personal/cryptobot/venv/lib/python3.8/site-packages/yaml/reader.py", line 143, in check_printable
    raise ReaderError(self.name, position, ord(character),
yaml.reader.ReaderError: unacceptable character #x0000: special characters are not allowed
  in "/Users/darrenpaul/Documents/development/personal/cryptobot/data/prices.yml", position 0

2022-04-16 09:32:49,157 | INFO | Running AlgoBot...
