2022-03-21 22:23:15,521 | WARNING | Error: Traceback (most recent call last):
  File "/home/pi/cryptobot/venv/lib/python3.9/site-packages/urllib3/connection.py", line 174, in _new_conn
    conn = connection.create_connection(
  File "/home/pi/cryptobot/venv/lib/python3.9/site-packages/urllib3/util/connection.py", line 72, in create_connection
    for res in socket.getaddrinfo(host, port, family, socket.SOCK_STREAM):
  File "/usr/lib/python3.9/socket.py", line 953, in getaddrinfo
    for res in _socket.getaddrinfo(host, port, family, type, proto, flags):
socket.gaierror: [Errno -3] Temporary failure in name resolution

During handling of the above exception, another exception occurred:

Traceback (most recent call last):
  File "/home/pi/cryptobot/venv/lib/python3.9/site-packages/urllib3/connectionpool.py", line 703, in urlopen
    httplib_response = self._make_request(
  File "/home/pi/cryptobot/venv/lib/python3.9/site-packages/urllib3/connectionpool.py", line 386, in _make_request
    self._validate_conn(conn)
  File "/home/pi/cryptobot/venv/lib/python3.9/site-packages/urllib3/connectionpool.py", line 1040, in _validate_conn
    conn.connect()
  File "/home/pi/cryptobot/venv/lib/python3.9/site-packages/urllib3/connection.py", line 358, in connect
    conn = self._new_conn()
  File "/home/pi/cryptobot/venv/lib/python3.9/site-packages/urllib3/connection.py", line 186, in _new_conn
    raise NewConnectionError(
urllib3.exceptions.NewConnectionError: <urllib3.connection.HTTPSConnection object at 0x730df700>: Failed to establish a new connection: [Errno -3] Temporary failure in name resolution

During handling of the above exception, another exception occurred:

Traceback (most recent call last):
  File "/home/pi/cryptobot/venv/lib/python3.9/site-packages/requests/adapters.py", line 440, in send
    resp = conn.urlopen(
  File "/home/pi/cryptobot/venv/lib/python3.9/site-packages/urllib3/connectionpool.py", line 785, in urlopen
    retries = retries.increment(
  File "/home/pi/cryptobot/venv/lib/python3.9/site-packages/urllib3/util/retry.py", line 592, in increment
    raise MaxRetryError(_pool, url, error or ResponseError(cause))
urllib3.exceptions.MaxRetryError: HTTPSConnectionPool(host='api.luno.com', port=443): Max retries exceeded with url: /api/1/tickers?pair=XRPZAR (Caused by NewConnectionError('<urllib3.connection.HTTPSConnection object at 0x730df700>: Failed to establish a new connection: [Errno -3] Temporary failure in name resolution'))

During handling of the above exception, another exception occurred:

Traceback (most recent call last):
  File "/home/pi/cryptobot/main.py", line 156, in <module>
    main()
  File "/home/pi/cryptobot/main.py", line 150, in main
    schedule.run_pending()
  File "/home/pi/cryptobot/venv/lib/python3.9/site-packages/schedule/__init__.py", line 780, in run_pending
    default_scheduler.run_pending()
  File "/home/pi/cryptobot/venv/lib/python3.9/site-packages/schedule/__init__.py", line 100, in run_pending
    self._run_job(job)
  File "/home/pi/cryptobot/venv/lib/python3.9/site-packages/schedule/__init__.py", line 172, in _run_job
    ret = job.run()
  File "/home/pi/cryptobot/venv/lib/python3.9/site-packages/schedule/__init__.py", line 661, in run
    ret = self.job_func()
  File "/home/pi/cryptobot/main.py", line 108, in handle_buy_orders
    handle_update(bot)
  File "/home/pi/cryptobot/main.py", line 103, in handle_update
    bot.get_current_price()
  File "/home/pi/cryptobot/classes/price_manager.py", line 33, in get_current_price
    self.current_price = luno.getPriceTicker(self.trading_pair)
  File "/home/pi/cryptobot/modules/luno.py", line 92, in getPriceTicker
    return float(requests.get(f'{BASE_URL}1/tickers', params=params).json()['tickers'][0]['last_trade'])
  File "/home/pi/cryptobot/venv/lib/python3.9/site-packages/requests/api.py", line 75, in get
    return request('get', url, params=params, **kwargs)
  File "/home/pi/cryptobot/venv/lib/python3.9/site-packages/requests/api.py", line 61, in request
    return session.request(method=method, url=url, **kwargs)
  File "/home/pi/cryptobot/venv/lib/python3.9/site-packages/requests/sessions.py", line 529, in request
    resp = self.send(prep, **send_kwargs)
  File "/home/pi/cryptobot/venv/lib/python3.9/site-packages/requests/sessions.py", line 645, in send
    r = adapter.send(request, **kwargs)
  File "/home/pi/cryptobot/venv/lib/python3.9/site-packages/requests/adapters.py", line 519, in send
    raise ConnectionError(e, request=request)
requests.exceptions.ConnectionError: HTTPSConnectionPool(host='api.luno.com', port=443): Max retries exceeded with url: /api/1/tickers?pair=XRPZAR (Caused by NewConnectionError('<urllib3.connection.HTTPSConnection object at 0x730df700>: Failed to establish a new connection: [Errno -3] Temporary failure in name resolution'))

2022-03-21 22:23:15,521 | WARNING | Error: Traceback (most recent call last):
  File "/home/pi/cryptobot/venv/lib/python3.9/site-packages/urllib3/connection.py", line 174, in _new_conn
    conn = connection.create_connection(
  File "/home/pi/cryptobot/venv/lib/python3.9/site-packages/urllib3/util/connection.py", line 72, in create_connection
    for res in socket.getaddrinfo(host, port, family, socket.SOCK_STREAM):
  File "/usr/lib/python3.9/socket.py", line 953, in getaddrinfo
    for res in _socket.getaddrinfo(host, port, family, type, proto, flags):
socket.gaierror: [Errno -3] Temporary failure in name resolution

During handling of the above exception, another exception occurred:

Traceback (most recent call last):
  File "/home/pi/cryptobot/venv/lib/python3.9/site-packages/urllib3/connectionpool.py", line 703, in urlopen
    httplib_response = self._make_request(
  File "/home/pi/cryptobot/venv/lib/python3.9/site-packages/urllib3/connectionpool.py", line 386, in _make_request
    self._validate_conn(conn)
  File "/home/pi/cryptobot/venv/lib/python3.9/site-packages/urllib3/connectionpool.py", line 1040, in _validate_conn
    conn.connect()
  File "/home/pi/cryptobot/venv/lib/python3.9/site-packages/urllib3/connection.py", line 358, in connect
    conn = self._new_conn()
  File "/home/pi/cryptobot/venv/lib/python3.9/site-packages/urllib3/connection.py", line 186, in _new_conn
    raise NewConnectionError(
urllib3.exceptions.NewConnectionError: <urllib3.connection.HTTPSConnection object at 0x730df700>: Failed to establish a new connection: [Errno -3] Temporary failure in name resolution

During handling of the above exception, another exception occurred:

Traceback (most recent call last):
  File "/home/pi/cryptobot/venv/lib/python3.9/site-packages/requests/adapters.py", line 440, in send
    resp = conn.urlopen(
  File "/home/pi/cryptobot/venv/lib/python3.9/site-packages/urllib3/connectionpool.py", line 785, in urlopen
    retries = retries.increment(
  File "/home/pi/cryptobot/venv/lib/python3.9/site-packages/urllib3/util/retry.py", line 592, in increment
    raise MaxRetryError(_pool, url, error or ResponseError(cause))
urllib3.exceptions.MaxRetryError: HTTPSConnectionPool(host='api.luno.com', port=443): Max retries exceeded with url: /api/1/tickers?pair=XRPZAR (Caused by NewConnectionError('<urllib3.connection.HTTPSConnection object at 0x730df700>: Failed to establish a new connection: [Errno -3] Temporary failure in name resolution'))

During handling of the above exception, another exception occurred:

Traceback (most recent call last):
  File "/home/pi/cryptobot/main.py", line 156, in <module>
    main()
  File "/home/pi/cryptobot/main.py", line 150, in main
    schedule.run_pending()
  File "/home/pi/cryptobot/venv/lib/python3.9/site-packages/schedule/__init__.py", line 780, in run_pending
    default_scheduler.run_pending()
  File "/home/pi/cryptobot/venv/lib/python3.9/site-packages/schedule/__init__.py", line 100, in run_pending
    self._run_job(job)
  File "/home/pi/cryptobot/venv/lib/python3.9/site-packages/schedule/__init__.py", line 172, in _run_job
    ret = job.run()
  File "/home/pi/cryptobot/venv/lib/python3.9/site-packages/schedule/__init__.py", line 661, in run
    ret = self.job_func()
  File "/home/pi/cryptobot/main.py", line 108, in handle_buy_orders
    handle_update(bot)
  File "/home/pi/cryptobot/main.py", line 103, in handle_update
    bot.get_current_price()
  File "/home/pi/cryptobot/classes/price_manager.py", line 33, in get_current_price
    self.current_price = luno.getPriceTicker(self.trading_pair)
  File "/home/pi/cryptobot/modules/luno.py", line 92, in getPriceTicker
    return float(requests.get(f'{BASE_URL}1/tickers', params=params).json()['tickers'][0]['last_trade'])
  File "/home/pi/cryptobot/venv/lib/python3.9/site-packages/requests/api.py", line 75, in get
    return request('get', url, params=params, **kwargs)
  File "/home/pi/cryptobot/venv/lib/python3.9/site-packages/requests/api.py", line 61, in request
    return session.request(method=method, url=url, **kwargs)
  File "/home/pi/cryptobot/venv/lib/python3.9/site-packages/requests/sessions.py", line 529, in request
    resp = self.send(prep, **send_kwargs)
  File "/home/pi/cryptobot/venv/lib/python3.9/site-packages/requests/sessions.py", line 645, in send
    r = adapter.send(request, **kwargs)
  File "/home/pi/cryptobot/venv/lib/python3.9/site-packages/requests/adapters.py", line 519, in send
    raise ConnectionError(e, request=request)
requests.exceptions.ConnectionError: HTTPSConnectionPool(host='api.luno.com', port=443): Max retries exceeded with url: /api/1/tickers?pair=XRPZAR (Caused by NewConnectionError('<urllib3.connection.HTTPSConnection object at 0x730df700>: Failed to establish a new connection: [Errno -3] Temporary failure in name resolution'))

